<?xml version="1.0" ?>
<!-- =================================================================================== -->
<!-- |    This document was autogenerated by xacro from /home/kimjaen/vuasrl_ws/src/vuasrl_manipulation/urdf/vuasrl_manipulation.urdf.xacro | -->
<!-- |    EDITING THIS FILE BY HAND IS NOT RECOMMENDED                                 | -->
<!-- =================================================================================== -->
<robot name="vuasrl_manipulation">
    <!-- Link1 -->
    <RefLink ref="link1" />
    <!-- Link2 -->
    <RefLink ref="link2" />
    <!-- Link3 -->
    <RefLink ref="link3" />
    <!-- Link4 -->
    <RefLink ref="link4" />
    <!-- Link5 -->
    <RefLink ref="link5" />
    <!-- gripper_link -->
    <RefLink ref="gripper" />
    <!-- gripper_link_sub -->
    <RefLink ref="gripper_sub" />
    <!-- end effector link -->
    <gazebo reference="end_effector_link">
        <material>Gazebo/Red</material>
        <plugin name="gazebo_ros_control">
            <robotNamespace>/</robotNamespace>
        </plugin>
    </gazebo>
    <!-- ros_control plugin -->
    <gazebo>
        <plugin filename="libgazebo_ros_control.so" name="gazebo_ros_control">
            <controlPeriod>0.001</controlPeriod>
            <robotNamespace>/vuasrl_manipulation</robotNamespace>
            <robotSimType>gazebo_ros_control/DefaultRobotHWSim</robotSimType>
            <legacyModeNS>true</legacyModeNS>
        </plugin>
    </gazebo>
    <!-- <gazebo> -->
    <!-- loading plugin: mimic joints works in gazebo now -->
    <!--  <plugin name="gazebo_gripper_ros_control" filename="libroboticsgroup_gazebo_mimic_joint_plugin.so">
      <joint>grip_joint</joint>
      <mimicJoint>grip_joint_sub</mimicJoint>
      <multiplier>1.0</multiplier>
      <offset>0.0</offset>
      <hasPID>/gazebo_ros_control/pid_gains/gripper_joint_sub</hasPID>
    </plugin>
  </gazebo> -->
    <transmission name="tran1">
        <type>transmission_interface/SimpleTransmission</type>
        <joint name="joint1">
            <hardwareInterface>hardware_interface/PositionJointInterface</hardwareInterface>
        </joint>
        <actuator name="motor1">
            <hardwareInterface>hardware_interface/PositionJointInterface</hardwareInterface>
            <mechanicalReduction>1</mechanicalReduction>
        </actuator>
    </transmission>
    <transmission name="tran2">
        <type>transmission_interface/SimpleTransmission</type>
        <joint name="joint2">
            <hardwareInterface>hardware_interface/PositionJointInterface</hardwareInterface>
        </joint>
        <actuator name="motor2">
            <hardwareInterface>hardware_interface/PositionJointInterface</hardwareInterface>
            <mechanicalReduction>1</mechanicalReduction>
        </actuator>
    </transmission>
    <transmission name="tran3">
        <type>transmission_interface/SimpleTransmission</type>
        <joint name="joint3">
            <hardwareInterface>hardware_interface/PositionJointInterface</hardwareInterface>
        </joint>
        <actuator name="motor3">
            <hardwareInterface>hardware_interface/PositionJointInterface</hardwareInterface>
            <mechanicalReduction>1</mechanicalReduction>
        </actuator>
    </transmission>
    <transmission name="tran4">
        <type>transmission_interface/SimpleTransmission</type>
        <joint name="joint4">
            <hardwareInterface>hardware_interface/PositionJointInterface</hardwareInterface>
        </joint>
        <actuator name="motor4">
            <hardwareInterface>hardware_interface/PositionJointInterface</hardwareInterface>
            <mechanicalReduction>1</mechanicalReduction>
        </actuator>
    </transmission>
    <transmission name="tran5">
        <type>transmission_interface/SimpleTransmission</type>
        <joint name="grip_joint">
            <hardwareInterface>hardware_interface/EffortJointInterface</hardwareInterface>
        </joint>
        <actuator name="motor5">
            <hardwareInterface>hardware_interface/EffortJointInterface</hardwareInterface>
            <mechanicalReduction>1</mechanicalReduction>
        </actuator>
    </transmission>
    <transmission name="tran6">
        <type>transmission_interface/SimpleTransmission</type>
        <joint name="grip_joint_sub">
            <hardwareInterface>hardware_interface/EffortJointInterface</hardwareInterface>
        </joint>
        <actuator name="motor6">
            <hardwareInterface>hardware_interface/EffortJointInterface</hardwareInterface>
            <mechanicalReduction>1</mechanicalReduction>
        </actuator>
    </transmission>
    <link name="link1">
        <inertial>
            <origin rpy="0 0 0" xyz="0.0001816853136070254 -2.1915878376977466e-17 0.020129887613482035" />
            <mass value="7.9119962e-02" />
            <inertia ixx="0.002145" ixy="-0.0" ixz="-1.3e-05" iyy="0.004951" iyz="-0.0" izz="0.006213" />
        </inertial>
        <visual>
            <origin rpy="0 0 0" xyz="0 0 0" />
            <geometry>
                <mesh filename="package://vuasrl_manipulation/meshes/link1.stl" scale="0.001 0.001 0.001" />
            </geometry>
            <material name="silver" />
        </visual>
        <collision>
            <origin rpy="0 0 0" xyz="0 0 0" />
            <geometry>
                <mesh filename="package://vuasrl_manipulation/meshes/link1.stl" scale="0.001 0.001 0.001" />
            </geometry>
        </collision>
    </link>
    <link name="link2">
        <inertial>
            <origin rpy="0 0 0" xyz="-2.328586629074536e-11 -2.8877387782838815e-10 0.020681716416087625" />
            <mass value="9.8406837e-02" />
            <inertia ixx="0.000355" ixy="0.0" ixz="0.0" iyy="0.00039" iyz="-0.0" izz="0.000302" />
        </inertial>
        <visual>
            <origin rpy="0 0 0" xyz="-0.03 -0.0 -0.048" />
            <geometry>
                <mesh filename="package://vuasrl_manipulation/meshes/link2.stl" scale="0.001 0.001 0.001" />
            </geometry>
            <material name="silver" />
        </visual>
        <collision>
            <origin rpy="0 0 0" xyz="-0.03 -0.0 -0.048" />
            <geometry>
                <mesh filename="package://vuasrl_manipulation/meshes/link2.stl" scale="0.001 0.001 0.001" />
            </geometry>
        </collision>
    </link>
    <link name="link3">
        <inertial>
            <origin rpy="0 0 0" xyz="-0.004542317857195898 0.0005782036806908492 0.09874905854464662" />
            <mass value="1.3850917e-01" />
            <inertia ixx="0.009439" ixy="-1e-06" ixz="0.000653" iyy="0.009407" iyz="1.5e-05" izz="0.0009" />
        </inertial>
        <visual>
            <origin rpy="0 0 0" xyz="-0.03 -0.0 -0.078" />
            <geometry>
                <mesh filename="package://vuasrl_manipulation/meshes/link3.stl" scale="0.001 0.001 0.001" />
            </geometry>
            <material name="silver" />
        </visual>
        <collision>
            <origin rpy="0 0 0" xyz="-0.03 -0.0 -0.078" />
            <geometry>
                <mesh filename="package://vuasrl_manipulation/meshes/link3.stl" scale="0.001 0.001 0.001" />
            </geometry>
        </collision>
    </link>
    <link name="link4">
        <inertial>
            <origin rpy="0 0 0" xyz="4.336808689942018e-18 0.0005787515631340847 0.10231346303330496" />
            <mass value="1.3274562e-01" />
            <inertia ixx="0.010801" ixy="0.0" ixz="0.0" iyy="0.010515" iyz="1.6e-05" izz="0.000691" />
        </inertial>
        <visual>
            <origin rpy="0 0 0" xyz="-0.005 -0.0005 -0.243" />
            <geometry>
                <mesh filename="package://vuasrl_manipulation/meshes/link4.stl" scale="0.001 0.001 0.001" />
            </geometry>
            <material name="silver" />
        </visual>
        <collision>
            <origin rpy="0 0 0" xyz="-0.005 -0.0005 -0.243" />
            <geometry>
                <mesh filename="package://vuasrl_manipulation/meshes/link4.stl" scale="0.001 0.001 0.001" />
            </geometry>
        </collision>
    </link>
    <link name="link5">
        <inertial>
            <origin rpy="0 0 0" xyz="2.8536201179818477e-16 -5.72784007724092e-15 0.04451102048440414" />
            <mass value="1.4327573e-01" />
            <inertia ixx="0.00218" ixy="-0.0" ixz="-0.0" iyy="0.00154" iyz="0.0" izz="0.000828" />
        </inertial>
        <visual>
            <origin rpy="0 0 0" xyz="-0.005 -0.001 -0.433" />
            <geometry>
                <mesh filename="package://vuasrl_manipulation/meshes/link5.stl" scale="0.001 0.001 0.001" />
            </geometry>
            <material name="silver" />
        </visual>
        <collision>
            <origin rpy="0 0 0" xyz="-0.005 -0.001 -0.433" />
            <geometry>
                <mesh filename="package://vuasrl_manipulation/meshes/link5.stl" scale="0.001 0.001 0.001" />
            </geometry>
        </collision>
    </link>
    <link name="gripper">
        <inertial>
            <origin rpy="0 0 0" xyz="0 0 0" />
            <mass value="1.0e-03" />
            <inertia ixx="1.0e-03" ixy="0.0" ixz="0.0" iyy="1.0e-03" iyz="0.0" izz="1.0e-03" />
        </inertial>
        <visual>
            <origin rpy="0 0 0" xyz="-0.01 0.033 -0.95715" />
            <geometry>
                <mesh filename="package://vuasrl_manipulation/meshes/grip.stl" scale="0.001 0.001 0.001" />
            </geometry>
            <material name="silver" />
        </visual>
        <collision>
            <origin rpy="0 0 0" xyz="-0.01 0.033 -0.95715" />
            <geometry>
                <mesh filename="package://vuasrl_manipulation/meshes/grip.stl" scale="0.001 0.001 0.001" />
            </geometry>
        </collision>
    </link>
    <link name="gripper_sub">
        <inertial>
            <origin rpy="0 0 0" xyz="0 0 0" />
            <mass value="1.0e-03" />
            <inertia ixx="1.0e-03" ixy="0.0" ixz="0.0" iyy="1.0e-03" iyz="0.0" izz="1.0e-03" />
        </inertial>
        <visual>
            <origin rpy="0 0 0" xyz="-0.01 -0.037 -0.95715" />
            <geometry>
                <mesh filename="package://vuasrl_manipulation/meshes/grip_sub.stl" scale="0.001 0.001 0.001" />
            </geometry>
            <material name="silver" />
        </visual>
        <collision>
            <origin rpy="0 0 0" xyz="-0.01 -0.037 -0.95715" />
            <geometry>
                <mesh filename="package://vuasrl_manipulation/meshes/grip_sub.stl" scale="0.001 0.001 0.001" />
            </geometry>
        </collision>
    </link>
    <joint name="joint1" type="revolute">
        <origin rpy="0 0 0" xyz="0.03 0.0 0.048" />
        <parent link="link1" />
        <child link="link2" />
        <axis xyz="0.0 0.0 1.0" />
        <limit effort="1" lower="-2.827433388230814" upper="2.827433388230814" velocity="4.8" />
    </joint>
    <joint name="joint2" type="revolute">
        <origin rpy="0 0 0" xyz="0.0 0.0 0.03" />
        <parent link="link2" />
        <child link="link3" />
        <axis xyz="0.0 1.0 0.0" />
        <limit effort="1" lower="-1.790707812546182" upper="1.5707963267948966" velocity="4.8" />
    </joint>
    <joint name="joint3" type="revolute">
        <origin rpy="0 0 0" xyz="-0.025 0.0005 0.165" />
        <parent link="link3" />
        <child link="link4" />
        <axis xyz="0.0 1.0 0.0" />
        <limit effort="1" lower="-0.9424777960769379" upper="1.382300767579509" velocity="4.8" />
    </joint>
    <joint name="joint4" type="revolute">
        <origin rpy="0 0 0" xyz="0.0 0.0005 0.19" />
        <parent link="link4" />
        <child link="link5" />
        <axis xyz="0.0 1.0 0.0" />
        <limit effort="1" lower="-1.790707812546182" upper="2.0420352248333655" velocity="4.8" />
    </joint>
    <joint name="grip_joint" type="prismatic">
        <origin rpy="0 0 0" xyz="0.005 -0.034 0.52415" />
        <parent link="link5" />
        <child link="gripper" />
        <axis xyz="0.0 1.0 0.0" />
        <limit effort="1" lower="-0.010" upper="0.019" velocity="4.8" />
    </joint>
    <joint name="grip_joint_sub" type="prismatic">
        <origin rpy="0 0 0" xyz="0.005 0.036 0.52415" />
        <parent link="link5" />
        <child link="gripper_sub" />
        <axis xyz="0.0 -1.0 0.0" />
        <limit effort="1" lower="-0.010" upper="0.019" velocity="4.8" />
        <!--  <mimic joint="grip_joint" multiplier="1"/> -->
    </joint>
    <!-- end effector joint -->
    <joint name="end_effector_joint" type="fixed">
        <origin rpy="0 0 0" xyz="0.0 0.0 0.115" />
        <parent link="link5" />
        <child link="end_effector_link" />
    </joint>
    <!-- end effector link -->
    <link name="end_effector_link">
        <visual>
            <origin rpy="0 0 0" xyz="0 0 0" />
            <geometry>
                <box size="0.01 0.01 0.01" />
            </geometry>
            <material name="red" />
        </visual>
        <collision>
            <origin rpy="0 0 0" xyz="0 0 0" />
            <geometry>
                <box size="0.01 0.01 0.01" />
            </geometry>
        </collision>
        <inertial>
            <origin rpy="0 0 0" xyz="0 0 0" />
            <mass value="1.0e-03" />
            <inertia ixx="1.0e-03" ixy="0.0" ixz="0.0" iyy="1.0e-03" iyz="0.0" izz="1.0e-03" />
        </inertial>
    </link>
    <!-- Init colour -->
    <material name="black">
        <color rgba="0.0 0.0 0.0 1.0" />
    </material>
    <material name="dark">
        <color rgba="0.3 0.3 0.3 1.0" />
    </material>
    <material name="light_black">
        <color rgba="0.4 0.4 0.4 1.0" />
    </material>
    <material name="blue">
        <color rgba="0.0 0.0 0.8 1.0" />
    </material>
    <material name="green">
        <color rgba="0.0 0.8 0.0 1.0" />
    </material>
    <material name="grey">
        <color rgba="0.5 0.5 0.5 1.0" />
    </material>
    <material name="orange">
        <color rgba="1.0 0.4235294117647059 0.0392156862745098 1.0" />
    </material>
    <material name="brown">
        <color rgba="0.8705882352941177 0.8117647058823529 0.7647058823529411 1.0" />
    </material>
    <material name="red">
        <color rgba="0.8 0.0 0.0 1.0" />
    </material>
    <material name="white">
        <color rgba="1.0 1.0 1.0 1.0" />
    </material>
    <material name="silver">
        <color rgba="0.700 0.700 0.700 1.000" />
    </material>
    <transmission name="rb_base_tran">
        <type>transmission_interface/SimpleTransmission</type>
        <joint name="rb_base">
            <hardwareInterface>hardware_interface/EffortJointInterface</hardwareInterface>
        </joint>
        <actuator name="rb_base_actr">
            <hardwareInterface>hardware_interface/EffortJointInterface</hardwareInterface>
            <mechanicalReduction>1</mechanicalReduction>
        </actuator>
    </transmission>
    <transmission name="lb_base_tran">
        <type>transmission_interface/SimpleTransmission</type>
        <joint name="lb_base">
            <hardwareInterface>hardware_interface/EffortJointInterface</hardwareInterface>
        </joint>
        <actuator name="lb_base_actr">
            <hardwareInterface>hardware_interface/EffortJointInterface</hardwareInterface>
            <mechanicalReduction>1</mechanicalReduction>
        </actuator>
    </transmission>
    <transmission name="rf_base_tran">
        <type>transmission_interface/SimpleTransmission</type>
        <joint name="rf_base">
            <hardwareInterface>hardware_interface/EffortJointInterface</hardwareInterface>
        </joint>
        <actuator name="rf_base_actr">
            <hardwareInterface>hardware_interface/EffortJointInterface</hardwareInterface>
            <mechanicalReduction>1</mechanicalReduction>
        </actuator>
    </transmission>
    <transmission name="lf_base_tran">
        <type>transmission_interface/SimpleTransmission</type>
        <joint name="lf_base">
            <hardwareInterface>hardware_interface/EffortJointInterface</hardwareInterface>
        </joint>
        <actuator name="lf_base_actr">
            <hardwareInterface>hardware_interface/EffortJointInterface</hardwareInterface>
            <mechanicalReduction>1</mechanicalReduction>
        </actuator>
    </transmission>
    <material name="Cam_Color">
        <color rgba="0.0 0.0 0.75 1.0" />
    </material>
    <gazebo>
        <plugin filename="libgazebo_ros_control.so" name="control" />
    </gazebo>
    <gazebo reference="base_link">
        <material>Gazebo/Grey</material>
        <mu1>0.2</mu1>
        <mu2>0.2</mu2>
        <selfCollide>true</selfCollide>
        <gravity>true</gravity>
    </gazebo>
    <gazebo reference="rb_wheel">
        <material>Gazebo/DarkGrey</material>
        <mu1>15000</mu1>
        <mu2>15000</mu2>
        <selfCollide>true</selfCollide>
    </gazebo>
    <gazebo reference="lb_wheel">
        <material>Gazebo/DarkGrey</material>
        <mu1>15000</mu1>
        <mu2>15000</mu2>
        <selfCollide>true</selfCollide>
    </gazebo>
    <gazebo reference="rf_wheel">
        <material>Gazebo/DarkGrey</material>
        <mu1>0.2</mu1>
        <mu2>0.2</mu2>
        <selfCollide>true</selfCollide>
    </gazebo>
    <gazebo reference="lf_wheel">
        <material>Gazebo/DarkGrey</material>
        <mu1>0.2</mu1>
        <mu2>0.2</mu2>
        <selfCollide>true</selfCollide>
    </gazebo>
    <gazebo>
        <plugin filename="libgazebo_ros_diff_drive.so" name="differential_drive_controller">
            <alwaysOn>true</alwaysOn>
            <updateRate>10</updateRate>
            <legacyMode>false</legacyMode>
            <leftJoint>lb_base</leftJoint>
            <rightJoint>rb_base</rightJoint>
            <wheelSeparation>0.12</wheelSeparation>
            <wheelDiameter>0.130</wheelDiameter>
            <commandTopic>cmd_vel</commandTopic>
            <odometryTopic>vuasrl/odom</odometryTopic>
            <odometryFrame>vuasrl/odom</odometryFrame>
            <robotBaseFrame>base_link</robotBaseFrame>
            <publishTf>1</publishTf>
            <publishOdom>true</publishOdom>
            <publishWheelTF>false</publishWheelTF>
            <publishWheelJointState>false</publishWheelJointState>
            <rosDebugLevel>na</rosDebugLevel>
            <wheelAcceleration>1.0</wheelAcceleration>
            <wheelTorque>20</wheelTorque>
            <odometrySource>world</odometrySource>
        </plugin>
    </gazebo>
    <!-- imu -->
    <gazebo reference="imu_link">
        <gravity>false</gravity>
        <sensor name="imu_sensor" type="imu">
            <always_on>true</always_on>
            <update_rate>100</update_rate>
            <visualize>true</visualize>
            <topic>__default_topic__</topic>
            <plugin filename="libgazebo_ros_imu_sensor.so" name="imu_plugin">
                <topicName>imu</topicName>
                <bodyName>imu_link</bodyName>
                <updateRateHZ>10.0</updateRateHZ>
                <gaussianNoise>0.0</gaussianNoise>
                <xyzOffset>0 0 0</xyzOffset>
                <rpyOffset>0 0 0</rpyOffset>
                <frameName>imu_link</frameName>
                <initialOrientationAsReference>false</initialOrientationAsReference>
            </plugin>
            <pose>0 0 0 0 0 0</pose>
        </sensor>
    </gazebo>
    <!-- ouster -->
    <gazebo reference="ouster_link">
        <sensor name="ouster_sensor" type="ray">
            <visualize>0</visualize>
            <update_rate>10</update_rate>
            <ray>
                <scan>
                    <horizontal>
                        <samples>512</samples>
                        <resolution>1</resolution>
                        <min_angle>-3.14159</min_angle>
                        <max_angle>3.14159</max_angle>
                    </horizontal>
                    <vertical>
                        <samples>32</samples>
                        <resolution>1</resolution>
                        <min_angle>-0.349</min_angle>
                        <max_angle>0.349</max_angle>
                    </vertical>
                </scan>
                <range>
                    <min>0.05</min>
                    <max>120.0</max>
                    <resolution>0.01</resolution>
                </range>
                <noise>
                    <type>gaussian</type>
                    <mean>0</mean>
                    <stddev>0.01</stddev>
                </noise>
            </ray>
            <plugin filename="libgazebo_ros_ouster_laser.so" name="gazebo_ros_laser_controller">
                <topicName>/os_cloud_node/points</topicName>
                <bodyName>ouster_link</bodyName>
                <frameName>ouster_link</frameName>
                <min_range>0.05</min_range>
                <max_range>120.0</max_range>
                <gaussianNoise>0.01</gaussianNoise>
            </plugin>
        </sensor>
    </gazebo>
    <!-- frames in the center of the camera -->
    <joint name="mani_camera_joint" type="fixed">
        <origin rpy="0.0 6.283185307179586 0.0" xyz="0.1345 -0.0015 0.1" />
        <parent link="base_link" />
        <child link="mani_camera_link" />
    </joint>
    <link name="mani_camera_link">
        <inertial>
            <origin rpy="0 0 0" xyz="-0.00936000000 -0.00003000000 -0.00273000000" />
            <mass value="0.21970000000" />
            <inertia ixx="0.00000429247" ixy="0.00000000000" ixz="0.00000002565" iyy="0.00000008027" iyz="0.00000000000" izz="0.00000427339" />
        </inertial>
        <visual>
            <geometry>
                <!--
          <box size="0.06 0.1 0.03" />
        	-->
                <mesh filename="package://tugcar_description/meshes/sensors/xtion_pro_live/xtion_pro_live.stl" />
            </geometry>
            <material name="Cam_Color" />
        </visual>
        <collision>
            <geometry>
                <mesh filename="package://tugcar_description/meshes/sensors/xtion_pro_live/xtion_pro_live.dae" />
            </geometry>
        </collision>
    </link>
    <joint name="mani_camera_optical_joint" type="fixed">
        <origin rpy="-1.5707963267948966 0.0 -1.5707963267948966" xyz="0 0 0" />
        <parent link="mani_camera_link" />
        <child link="mani_camera_optical_frame" />
    </joint>
    <link name="mani_camera_optical_frame">
        <dummy_inertial />
    </link>
    <!-- Depth sensor frames -->
    <joint name="mani_camera_depth_joint" type="fixed">
        <origin rpy="0 0 0" xyz="0.0 0.049 0.0" />
        <parent link="mani_camera_link" />
        <child link="mani_camera_depth_frame" />
    </joint>
    <link name="mani_camera_depth_frame">
        <dummy_inertial />
    </link>
    <joint name="mani_camera_depth_optical_joint" type="fixed">
        <origin rpy="-1.5707963267948966 0.0 -1.5707963267948966" xyz="0 0 0" />
        <parent link="mani_camera_depth_frame" />
        <child link="mani_camera_depth_optical_frame" />
    </joint>
    <link name="mani_camera_depth_optical_frame">
        <dummy_inertial />
    </link>
    <!-- RGB sensor frames -->
    <joint name="mani_camera_rgb_joint" type="fixed">
        <origin rpy="0 0 0" xyz="0.0 0.022 0.0" />
        <parent link="mani_camera_link" />
        <child link="mani_camera_rgb_frame" />
    </joint>
    <link name="mani_camera_rgb_frame">
        <dummy_inertial />
    </link>
    <joint name="mani_camera_rgb_optical_joint" type="fixed">
        <origin rpy="-1.5707963267948966 0.0 -1.5707963267948966" xyz="0 0 0" />
        <parent link="mani_camera_rgb_frame" />
        <child link="mani_camera_rgb_optical_frame" />
    </joint>
    <link name="mani_camera_rgb_optical_frame">
        <dummy_inertial />
    </link>
    <gazebo reference="mani_camera_link">
        <!-- Depth (IR) -->
        <sensor name="mani_camera_frame_sensor" type="depth">
            <always_on>true</always_on>
            <update_rate>6.0</update_rate>
            <camera>
                <horizontal_fov>1.0122909661567112</horizontal_fov>
                <image>
                    <format>R8G8B8</format>
                    <width>800</width>
                    <height>600</height>
                </image>
                <clip>
                    <near>0.05</near>
                    <far>1.5</far>
                </clip>
            </camera>
            <plugin filename="libgazebo_ros_openni_kinect.so" name="mani_camera_depth_controller">
                <alwaysOn>true</alwaysOn>
                <updateRate>6.0</updateRate>
                <cameraName>mani_camera</cameraName>
                <imageTopicName>ir/image_raw</imageTopicName>
                <cameraInfoTopicName>ir/camera_info</cameraInfoTopicName>
                <depthImageTopicName>depth/image_raw</depthImageTopicName>
                <depthImageCameraInfoTopicName>depth/camera_info</depthImageCameraInfoTopicName>
                <pointCloudTopicName>depth/points</pointCloudTopicName>
                <frameName>mani_camera_optical_frame</frameName>
                <pointCloudCutoff>0.05</pointCloudCutoff>
                <pointCloudCutoffMax>5</pointCloudCutoffMax>
                <rangeMax>1.5</rangeMax>
                <!-- Distortion parameters not supported in gazebo 1.9.* plugins -->
                <!--distortionK1>0.00000001</distortionK1>
          <distortionK2>0.00000001</distortionK2>
          <distortionK3>0.00000001</distortionK3>
          <distortionT1>0.00000001</distortionT1>
          <distortionT2>0.00000001</distortionT2-->
            </plugin>
        </sensor>
        <!-- RGB -->
        <sensor name="mani_camera_frame_sensor" type="rgb">
            <always_on>true</always_on>
            <update_rate>6.0</update_rate>
            <camera>
                <horizontal_fov>1.0122909661567112</horizontal_fov>
                <image>
                    <format>R8G8B8</format>
                    <width>800</width>
                    <height>600</height>
                </image>
                <clip>
                    <near>0.05</near>
                    <far>1.5</far>
                </clip>
            </camera>
            <plugin filename="libgazebo_ros_openni_kinect.so" name="mani_camera_rgb_controller">
                <alwaysOn>true</alwaysOn>
                <updateRate>6.0</updateRate>
                <cameraName>mani_camera</cameraName>
                <imageTopicName>rgb/image_raw</imageTopicName>
                <cameraInfoTopicName>rgb/camera_info</cameraInfoTopicName>
                <pointCloudTopicName>rgb/points</pointCloudTopicName>
                <depthImageTopicName>depth/image_raw</depthImageTopicName>
                <depthImageCameraInfoTopicName>depth/camera_info</depthImageCameraInfoTopicName>
                <frameName>mani_camera_optical_frame</frameName>
                <pointCloudCutoff>0.05</pointCloudCutoff>
                <pointCloudCutoffMax>5</pointCloudCutoffMax>
                <rangeMax>1.5</rangeMax>
            </plugin>
        </sensor>
    </gazebo>
    <link name="base_footprint" />
    <link name="base_link">
        <inertial>
            <origin rpy="0 0 0" xyz="-0.0024815786222996896 8.508916291582655e-12 0.0794086767825376" />
            <mass value="4.692054269661653" />
            <inertia ixx="0.016864" ixy="0.0" ixz="-0.000207" iyy="0.034781" iyz="0.0" izz="0.046341" />
        </inertial>
        <visual>
            <origin rpy="0 0 0" xyz="0 0 0" />
            <geometry>
                <mesh filename="package://vuasrl_car_description/meshes/base_link.stl" scale="0.001 0.001 0.001" />
            </geometry>
            <material name="light_black" />
        </visual>
        <collision>
            <origin rpy="0 0 0" xyz="0 0 0" />
            <geometry>
                <mesh filename="package://vuasrl_car_description/meshes/base_link.stl" scale="0.001 0.001 0.001" />
            </geometry>
        </collision>
    </link>
    <link name="rb_wheel">
        <inertial>
            <origin rpy="0 0 0" xyz="-1.0699774399824946e-14 -0.012500000000000011 0.0" />
            <mass value="0.30048849691250473" />
            <inertia ixx="0.000333" ixy="0.0" ixz="0.0" iyy="0.000635" iyz="0.0" izz="0.000333" />
        </inertial>
        <visual>
            <origin rpy="0 0 0" xyz="0.1 0.11 -0.065" />
            <geometry>
                <mesh filename="package://vuasrl_car_description/meshes/rb_wheel_1.stl" scale="0.001 0.001 0.001" />
            </geometry>
            <material name="brown" />
        </visual>
        <collision>
            <origin rpy="0 0 0" xyz="0.1 0.11 -0.065" />
            <geometry>
                <mesh filename="package://vuasrl_car_description/meshes/rb_wheel_1.stl" scale="0.001 0.001 0.001" />
            </geometry>
        </collision>
    </link>
    <link name="lb_wheel">
        <inertial>
            <origin rpy="0 0 0" xyz="-1.0685896612017132e-14 0.012500000000000011 -1.3877787807814457e-17" />
            <mass value="0.30048849691250473" />
            <inertia ixx="0.000333" ixy="0.0" ixz="0.0" iyy="0.000635" iyz="0.0" izz="0.000333" />
        </inertial>
        <visual>
            <origin rpy="0 0 0" xyz="0.1 -0.11 -0.065" />
            <geometry>
                <mesh filename="package://vuasrl_car_description/meshes/lb_wheel_1.stl" scale="0.001 0.001 0.001" />
            </geometry>
            <material name="brown" />
        </visual>
        <collision>
            <origin rpy="0 0 0" xyz="0.1 -0.11 -0.065" />
            <geometry>
                <mesh filename="package://vuasrl_car_description/meshes/lb_wheel_1.stl" scale="0.001 0.001 0.001" />
            </geometry>
        </collision>
    </link>
    <link name="rf_wheel">
        <inertial>
            <origin rpy="0 0 0" xyz="1.0685896612017132e-14 -0.012499999999999997 1.3877787807814457e-17" />
            <mass value="0.3004884969125047" />
            <inertia ixx="0.000333" ixy="0.0" ixz="0.0" iyy="0.000635" iyz="-0.0" izz="0.000333" />
        </inertial>
        <visual>
            <origin rpy="0 0 0" xyz="-0.1 0.11 -0.065" />
            <geometry>
                <mesh filename="package://vuasrl_car_description/meshes/rf_wheel_1.stl" scale="0.001 0.001 0.001" />
            </geometry>
            <material name="brown" />
        </visual>
        <collision>
            <origin rpy="0 0 0" xyz="-0.1 0.11 -0.065" />
            <geometry>
                <mesh filename="package://vuasrl_car_description/meshes/rf_wheel_1.stl" scale="0.001 0.001 0.001" />
            </geometry>
        </collision>
    </link>
    <link name="lf_wheel">
        <inertial>
            <origin rpy="0 0 0" xyz="1.0685896612017132e-14 0.012499999999999997 0.0" />
            <mass value="0.3004884969125047" />
            <inertia ixx="0.000333" ixy="0.0" ixz="0.0" iyy="0.000635" iyz="0.0" izz="0.000333" />
        </inertial>
        <visual>
            <origin rpy="0 0 0" xyz="-0.1 -0.11 -0.065" />
            <geometry>
                <mesh filename="package://vuasrl_car_description/meshes/lf_wheel_1.stl" scale="0.001 0.001 0.001" />
            </geometry>
            <material name="brown" />
        </visual>
        <collision>
            <origin rpy="0 0 0" xyz="-0.1 -0.11 -0.065" />
            <geometry>
                <mesh filename="package://vuasrl_car_description/meshes/lf_wheel_1.stl" scale="0.001 0.001 0.001" />
            </geometry>
        </collision>
    </link>
    <link name="ouster_link">
        <inertial>
            <origin rpy="0 0 0" xyz="-1.3877787807814457e-17 0.0 0.007571641576545857" />
            <mass value="0.22880119812327096" />
            <inertia ixx="4e-05" ixy="0.0" ixz="-0.0" iyy="4e-05" iyz="-0.0" izz="7.1e-05" />
        </inertial>
        <visual>
            <origin rpy="0 0 0" xyz="0.085 0.0 -0.15" />
            <geometry>
                <mesh filename="package://vuasrl_car_description/models/sensors/ouster_ros/meshes/os1_64.dae" scale="0.8 0.8 0.7" />
            </geometry>
            <material name="silver" />
        </visual>
        <collision>
            <origin rpy="0 0 0" xyz="0.085 0.0 -0.10" />
            <geometry>
                <mesh filename="package://vuasrl_car_description/models/sensors/ouster_ros/meshes/os1_64.dae" scale="0.8 0.8 0.7" />
            </geometry>
        </collision>
    </link>
    <link name="imu_link">
        <inertial>
            <origin rpy="0 0 0" xyz="0 0 0" />
            <mass value="0.1" />
            <inertia ixx="4e-05" ixy="0.0" ixz="-0.0" iyy="4e-05" iyz="-0.0" izz="7.1e-05" />
        </inertial>
        <visual>
            <origin rpy="0 0 0" xyz="0 0 0" />
            <geometry>
                <box size="0.01 0.02 0.01" />
            </geometry>
            <material name="white" />
        </visual>
        <collision>
            <geometry>
                <box size="0.01 0.02 0.01" />
            </geometry>
        </collision>
    </link>
    <joint name="base_joint" type="fixed">
        <parent link="base_footprint" />
        <child link="base_link" />
        <origin rpy="0 0 0" xyz="0 0 0.010" />
    </joint>
    <joint name="rb_base" type="continuous">
        <origin rpy="0 0 0" xyz="-0.1 -0.11 0.065" />
        <parent link="base_link" />
        <child link="rb_wheel" />
        <axis xyz="0.0 1.0 0.0" />
    </joint>
    <joint name="lb_base" type="continuous">
        <origin rpy="0 0 0" xyz="-0.1 0.11 0.065" />
        <parent link="base_link" />
        <child link="lb_wheel" />
        <axis xyz="0.0 1.0 0.0" />
    </joint>
    <joint name="rf_base" type="continuous">
        <origin rpy="0 0 0" xyz="0.1 -0.11 0.065" />
        <parent link="base_link" />
        <child link="rf_wheel" />
        <axis xyz="0.0 1.0 0.0" />
    </joint>
    <joint name="lf_base" type="continuous">
        <origin rpy="0 0 0" xyz="0.1 0.11 0.065" />
        <parent link="base_link" />
        <child link="lf_wheel" />
        <axis xyz="0.0 1.0 0.0" />
    </joint>
    <joint name="lidar_base" type="fixed">
        <origin rpy="0 0 0" xyz="0.0 0.0 0.30" />
        <parent link="base_link" />
        <child link="ouster_link" />
    </joint>
    <joint name="imu_joint" type="fixed">
        <parent link="base_link" />
        <child link="imu_link" />
        <origin rpy="0 0 0" xyz="0.03 0 0.125" />
    </joint>
    <!-- base_fixed joint-->
    <joint name="base_fixed" type="fixed">
        <origin rpy="0 0 0" xyz="-0.05 0.0 0.12" />
        <parent link="base_link" />
        <child link="link1" />
    </joint>
</robot>

