<?xml version="1.0" ?>
<robot name="tugcar" xmlns:xacro="http://www.ros.org/wiki/xacro">

<xacro:include filename="$(find tugcar_description)/urdf/materials.xacro" />
<xacro:include filename="$(find tugcar_description)/urdf/tugcar.trans" />
<xacro:include filename="$(find tugcar_description)/urdf/tugcar.gazebo" />
<link name="base_link">
  <inertial>
    <origin xyz="-0.03938896617200097 -1.2967475254059896e-08 0.029822081428879356" rpy="0 0 0"/>
    <mass value="4.927881110352107"/>
    <inertia ixx="0.016525" iyy="0.082056" izz="0.093665" ixy="0.0" iyz="-0.0" ixz="0.005358"/>
  </inertial>
  <visual>
    <origin xyz="0 0 0" rpy="0 0 0"/>
    <geometry>
      <mesh filename="package://tugcar_description/meshes/base_link.stl" scale="0.001 0.001 0.001"/>
    </geometry>
    <material name="silver"/>
  </visual>
  <collision>
    <origin xyz="0 0 0" rpy="0 0 0"/>
    <geometry>
      <mesh filename="package://tugcar_description/meshes/base_link.stl" scale="0.001 0.001 0.001"/>
    </geometry>
  </collision>
</link>

<link name="right_wheel_1">
  <inertial>
    <origin xyz="-6.022959908591474e-15 -0.0050000000000000044 2.42861286636753e-17" rpy="0 0 0"/>
    <mass value="0.0637159488596124"/>
    <inertia ixx="3.6e-05" iyy="7.2e-05" izz="3.6e-05" ixy="0.0" iyz="0.0" ixz="0.0"/>
  </inertial>
  <visual>
    <origin xyz="0.15 0.11 -0.025" rpy="0 0 0"/>
    <geometry>
      <mesh filename="package://tugcar_description/meshes/right_wheel_1.stl" scale="0.001 0.001 0.001"/>
    </geometry>
    <material name="silver"/>
  </visual>
  <collision>
    <origin xyz="0.15 0.11 -0.025" rpy="0 0 0"/>
    <geometry>
      <mesh filename="package://tugcar_description/meshes/right_wheel_1.stl" scale="0.001 0.001 0.001"/>
    </geometry>
  </collision>
</link>

<link name="left_wheel_1">
  <inertial>
    <origin xyz="5.9674487573602164e-15 0.005000000000000018 -6.245004513516506e-17" rpy="0 0 0"/>
    <mass value="0.06371594885961245"/>
    <inertia ixx="3.6e-05" iyy="7.2e-05" izz="3.6e-05" ixy="0.0" iyz="0.0" ixz="-0.0"/>
  </inertial>
  <visual>
    <origin xyz="0.15 -0.11 -0.025" rpy="0 0 0"/>
    <geometry>
      <mesh filename="package://tugcar_description/meshes/left_wheel_1.stl" scale="0.001 0.001 0.001"/>
    </geometry>
    <material name="silver"/>
  </visual>
  <collision>
    <origin xyz="0.15 -0.11 -0.025" rpy="0 0 0"/>
    <geometry>
      <mesh filename="package://tugcar_description/meshes/left_wheel_1.stl" scale="0.001 0.001 0.001"/>
    </geometry>
  </collision>
</link>

<link name="right_caster_1">
  <inertial>
    <origin xyz="0.0 -0.05 -0.009374999999999993" rpy="0 0 0"/>
    <mass value="0.2568906492779154"/>
    <inertia ixx="4.2e-05" iyy="4.2e-05" izz="6.4e-05" ixy="0.0" iyz="-0.0" ixz="0.0"/>
  </inertial>
  <visual>
    <origin xyz="-0.15 -0.0 -0.0" rpy="0 0 0"/>
    <geometry>
      <mesh filename="package://tugcar_description/meshes/right_caster_1.stl" scale="0.001 0.001 0.001"/>
    </geometry>
    <material name="silver"/>
  </visual>
  <collision>
    <origin xyz="-0.15 -0.0 -0.0" rpy="0 0 0"/>
    <geometry>
      <mesh filename="package://tugcar_description/meshes/right_caster_1.stl" scale="0.001 0.001 0.001"/>
    </geometry>
  </collision>
</link>

<link name="left_caster_1">
  <inertial>
    <origin xyz="0.0 0.05 -0.009374999999999993" rpy="0 0 0"/>
    <mass value="0.2568906492779154"/>
    <inertia ixx="4.2e-05" iyy="4.2e-05" izz="6.4e-05" ixy="0.0" iyz="0.0" ixz="0.0"/>
  </inertial>
  <visual>
    <origin xyz="-0.15 -0.0 -0.0" rpy="0 0 0"/>
    <geometry>
      <mesh filename="package://tugcar_description/meshes/left_caster_1.stl" scale="0.001 0.001 0.001"/>
    </geometry>
    <material name="silver"/>
  </visual>
  <collision>
    <origin xyz="-0.15 -0.0 -0.0" rpy="0 0 0"/>
    <geometry>
      <mesh filename="package://tugcar_description/meshes/left_caster_1.stl" scale="0.001 0.001 0.001"/>
    </geometry>
  </collision>
</link>

<link name="lidar_1">
  <inertial>
    <origin xyz="-2.7755575615628914e-17 -1.0141114778754762e-17 0.010078564780385421" rpy="0 0 0"/>
    <mass value="1.7600464950545989"/>
    <inertia ixx="0.001629" iyy="0.001629" izz="0.003142" ixy="-0.0" iyz="0.0" ixz="-0.0"/>
  </inertial>
  <visual>
    <origin xyz="0.15 -0.0 -0.1" rpy="0 0 0"/>
    <geometry>
      <mesh filename="package://tugcar_description/meshes/lidar_1.stl" scale="0.001 0.001 0.001"/>
    </geometry>
    <material name="silver"/>
  </visual>
  <collision>
    <origin xyz="0.15 -0.0 -0.1" rpy="0 0 0"/>
    <geometry>
      <mesh filename="package://tugcar_description/meshes/lidar_1.stl" scale="0.001 0.001 0.001"/>
    </geometry>
  </collision>
</link>

<link name="arm_link1_v1_1">
  <inertial>
    <origin xyz="0.0 0.0 0.020115052438651124" rpy="0 0 0"/>
    <mass value="0.045098090524002"/>
    <inertia ixx="2e-05" iyy="1.7e-05" izz="1.5e-05" ixy="-0.0" iyz="0.0" ixz="-0.0"/>
  </inertial>
  <visual>
    <origin xyz="-0.15 -0.0 -0.035" rpy="0 0 0"/>
    <geometry>
      <mesh filename="package://tugcar_description/meshes/arm_link1_v1_1.stl" scale="0.001 0.001 0.001"/>
    </geometry>
    <material name="silver"/>
  </visual>
  <collision>
    <origin xyz="-0.15 -0.0 -0.035" rpy="0 0 0"/>
    <geometry>
      <mesh filename="package://tugcar_description/meshes/arm_link1_v1_1.stl" scale="0.001 0.001 0.001"/>
    </geometry>
  </collision>
</link>

<link name="arm_set_v1_1">
  <inertial>
    <origin xyz="0.0 0.009999999999999997 0.07023916163853255" rpy="0 0 0"/>
    <mass value="0.2146877443306135"/>
    <inertia ixx="0.000354" iyy="0.000357" izz="5.5e-05" ixy="0.0" iyz="0.0" ixz="0.0"/>
  </inertial>
  <visual>
    <origin xyz="-0.15 0.01 -0.07" rpy="0 0 0"/>
    <geometry>
      <mesh filename="package://tugcar_description/meshes/arm_set_v1_1.stl" scale="0.001 0.001 0.001"/>
    </geometry>
    <material name="silver"/>
  </visual>
  <collision>
    <origin xyz="-0.15 0.01 -0.07" rpy="0 0 0"/>
    <geometry>
      <mesh filename="package://tugcar_description/meshes/arm_set_v1_1.stl" scale="0.001 0.001 0.001"/>
    </geometry>
  </collision>
</link>

<link name="arm_axle1_v2_1">
  <inertial>
    <origin xyz="0.0 0.02 0.0" rpy="0 0 0"/>
    <mass value="0.013292405642737589"/>
    <inertia ixx="2e-06" iyy="1e-06" izz="2e-06" ixy="0.0" iyz="0.0" ixz="0.0"/>
  </inertial>
  <visual>
    <origin xyz="-0.15 0.02 -0.07" rpy="0 0 0"/>
    <geometry>
      <mesh filename="package://tugcar_description/meshes/arm_axle1_v2_1.stl" scale="0.001 0.001 0.001"/>
    </geometry>
    <material name="silver"/>
  </visual>
  <collision>
    <origin xyz="-0.15 0.02 -0.07" rpy="0 0 0"/>
    <geometry>
      <mesh filename="package://tugcar_description/meshes/arm_axle1_v2_1.stl" scale="0.001 0.001 0.001"/>
    </geometry>
  </collision>
</link>

<link name="arm_link2_v2_1">
  <inertial>
    <origin xyz="0.0 6.680329842389699e-18 0.020115052438651138" rpy="0 0 0"/>
    <mass value="0.04509809052400196"/>
    <inertia ixx="2e-05" iyy="1.7e-05" izz="1.5e-05" ixy="0.0" iyz="0.0" ixz="0.0"/>
  </inertial>
  <visual>
    <origin xyz="-0.15 -0.0 -0.205" rpy="0 0 0"/>
    <geometry>
      <mesh filename="package://tugcar_description/meshes/arm_link2_v2_1.stl" scale="0.001 0.001 0.001"/>
    </geometry>
    <material name="silver"/>
  </visual>
  <collision>
    <origin xyz="-0.15 -0.0 -0.205" rpy="0 0 0"/>
    <geometry>
      <mesh filename="package://tugcar_description/meshes/arm_link2_v2_1.stl" scale="0.001 0.001 0.001"/>
    </geometry>
  </collision>
</link>

<link name="arm_set2_v1_1">
  <inertial>
    <origin xyz="0.07023916163853253 0.009999999999999992 5.551115123125783e-17" rpy="0 0 0"/>
    <mass value="0.2146877443306135"/>
    <inertia ixx="5.5e-05" iyy="0.000357" izz="0.000354" ixy="-0.0" iyz="-0.0" ixz="0.0"/>
  </inertial>
  <visual>
    <origin xyz="-0.15 0.01 -0.24" rpy="0 0 0"/>
    <geometry>
      <mesh filename="package://tugcar_description/meshes/arm_set2_v1_1.stl" scale="0.001 0.001 0.001"/>
    </geometry>
    <material name="silver"/>
  </visual>
  <collision>
    <origin xyz="-0.15 0.01 -0.24" rpy="0 0 0"/>
    <geometry>
      <mesh filename="package://tugcar_description/meshes/arm_set2_v1_1.stl" scale="0.001 0.001 0.001"/>
    </geometry>
  </collision>
</link>

<link name="arm_axle2_v1_1">
  <inertial>
    <origin xyz="0.0 0.02 -2.7755575615628914e-17" rpy="0 0 0"/>
    <mass value="0.013292405642737589"/>
    <inertia ixx="2e-06" iyy="1e-06" izz="2e-06" ixy="0.0" iyz="0.0" ixz="-0.0"/>
  </inertial>
  <visual>
    <origin xyz="-0.15 0.02 -0.24" rpy="0 0 0"/>
    <geometry>
      <mesh filename="package://tugcar_description/meshes/arm_axle2_v1_1.stl" scale="0.001 0.001 0.001"/>
    </geometry>
    <material name="silver"/>
  </visual>
  <collision>
    <origin xyz="-0.15 0.02 -0.24" rpy="0 0 0"/>
    <geometry>
      <mesh filename="package://tugcar_description/meshes/arm_axle2_v1_1.stl" scale="0.001 0.001 0.001"/>
    </geometry>
  </collision>
</link>

<link name="gripper_set_v2_1">
  <inertial>
    <origin xyz="0.0180645606481612 -1.5720092607937034e-11 5.551115123125783e-17" rpy="0 0 0"/>
    <mass value="0.08860286699530373"/>
    <inertia ixx="7.5e-05" iyy="1.6e-05" izz="7.5e-05" ixy="-0.0" iyz="0.0" ixz="0.0"/>
  </inertial>
  <visual>
    <origin xyz="-0.285 -0.0 -0.24" rpy="0 0 0"/>
    <geometry>
      <mesh filename="package://tugcar_description/meshes/gripper_set_v2_1.stl" scale="0.001 0.001 0.001"/>
    </geometry>
    <material name="silver"/>
  </visual>
  <collision>
    <origin xyz="-0.285 -0.0 -0.24" rpy="0 0 0"/>
    <geometry>
      <mesh filename="package://tugcar_description/meshes/gripper_set_v2_1.stl" scale="0.001 0.001 0.001"/>
    </geometry>
  </collision>
</link>

<link name="gripper_llink_v3_1">
  <inertial>
    <origin xyz="0.01168384972971892 6.938893903907228e-18 1.2370660051885807e-13" rpy="0 0 0"/>
    <mass value="0.0026186137577415146"/>
    <inertia ixx="0.0" iyy="0.0" izz="0.0" ixy="-0.0" iyz="0.0" ixz="0.0"/>
  </inertial>
  <visual>
    <origin xyz="-0.3 -0.04 -0.24" rpy="0 0 0"/>
    <geometry>
      <mesh filename="package://tugcar_description/meshes/gripper_llink_v3_1.stl" scale="0.001 0.001 0.001"/>
    </geometry>
    <material name="silver"/>
  </visual>
  <collision>
    <origin xyz="-0.3 -0.04 -0.24" rpy="0 0 0"/>
    <geometry>
      <mesh filename="package://tugcar_description/meshes/gripper_llink_v3_1.stl" scale="0.001 0.001 0.001"/>
    </geometry>
  </collision>
</link>

<link name="gripper_left_v3_1">
  <inertial>
    <origin xyz="0.02175320681597248 -0.00500550499347583 1.965094753586527e-14" rpy="0 0 0"/>
    <mass value="0.003832390408952286"/>
    <inertia ixx="0.0" iyy="1e-06" izz="1e-06" ixy="0.0" iyz="-0.0" ixz="0.0"/>
  </inertial>
  <visual>
    <origin xyz="-0.327 -0.04 -0.24" rpy="0 0 0"/>
    <geometry>
      <mesh filename="package://tugcar_description/meshes/gripper_left_v3_1.stl" scale="0.001 0.001 0.001"/>
    </geometry>
    <material name="silver"/>
  </visual>
  <collision>
    <origin xyz="-0.327 -0.04 -0.24" rpy="0 0 0"/>
    <geometry>
      <mesh filename="package://tugcar_description/meshes/gripper_left_v3_1.stl" scale="0.001 0.001 0.001"/>
    </geometry>
  </collision>
</link>

<link name="gripper_rlink_v3_1">
  <inertial>
    <origin xyz="0.01168384972971892 0.0 -1.7135440288917891e-10" rpy="0 0 0"/>
    <mass value="0.002618613757741515"/>
    <inertia ixx="0.0" iyy="0.0" izz="0.0" ixy="0.0" iyz="0.0" ixz="0.0"/>
  </inertial>
  <visual>
    <origin xyz="-0.3 0.04 -0.24" rpy="0 0 0"/>
    <geometry>
      <mesh filename="package://tugcar_description/meshes/gripper_rlink_v3_1.stl" scale="0.001 0.001 0.001"/>
    </geometry>
    <material name="silver"/>
  </visual>
  <collision>
    <origin xyz="-0.3 0.04 -0.24" rpy="0 0 0"/>
    <geometry>
      <mesh filename="package://tugcar_description/meshes/gripper_rlink_v3_1.stl" scale="0.001 0.001 0.001"/>
    </geometry>
  </collision>
</link>

<link name="gripper_right_v2_1">
  <inertial>
    <origin xyz="0.021753206869349173 0.005005505130163443 -3.261011460864438e-09" rpy="0 0 0"/>
    <mass value="0.0038323903638238137"/>
    <inertia ixx="0.0" iyy="1e-06" izz="1e-06" ixy="-0.0" iyz="0.0" ixz="-0.0"/>
  </inertial>
  <visual>
    <origin xyz="-0.327 0.04 -0.24" rpy="0 0 0"/>
    <geometry>
      <mesh filename="package://tugcar_description/meshes/gripper_right_v2_1.stl" scale="0.001 0.001 0.001"/>
    </geometry>
    <material name="silver"/>
  </visual>
  <collision>
    <origin xyz="-0.327 0.04 -0.24" rpy="0 0 0"/>
    <geometry>
      <mesh filename="package://tugcar_description/meshes/gripper_right_v2_1.stl" scale="0.001 0.001 0.001"/>
    </geometry>
  </collision>
</link>

<joint name="join_01" type="continuous">
  <origin xyz="-0.15 -0.11 0.025" rpy="0 0 0"/>
  <parent link="base_link"/>
  <child link="right_wheel_1"/>
  <axis xyz="0.0 -1.0 0.0"/>
</joint>

<joint name="joint_02" type="continuous">
  <origin xyz="-0.15 0.11 0.025" rpy="0 0 0"/>
  <parent link="base_link"/>
  <child link="left_wheel_1"/>
  <axis xyz="0.0 1.0 0.0"/>
</joint>

<joint name="right_jcaster" type="fixed">
  <origin xyz="0.15 0.0 0.0" rpy="0 0 0"/>
  <parent link="base_link"/>
  <child link="right_caster_1"/>
</joint>

<joint name="left_jcaster" type="fixed">
  <origin xyz="0.15 0.0 0.0" rpy="0 0 0"/>
  <parent link="base_link"/>
  <child link="left_caster_1"/>
</joint>

<joint name="lidar_j" type="fixed">
  <origin xyz="-0.15 0.0 0.1" rpy="0 0 0"/>
  <parent link="base_link"/>
  <child link="lidar_1"/>
</joint>

<joint name="joint_03" type="continuous">
  <origin xyz="0.15 0.0 0.035" rpy="0 0 0"/>
  <parent link="base_link"/>
  <child link="arm_link1_v1_1"/>
  <axis xyz="0.0 0.0 1.0"/>
</joint>

<joint name="joint_04" type="continuous">
  <origin xyz="0.0 -0.01 0.035" rpy="0 0 0"/>
  <parent link="arm_link1_v1_1"/>
  <child link="arm_set_v1_1"/>
  <axis xyz="0.0 1.0 0.0"/>
</joint>

<joint name="rigid_axle1" type="fixed">
  <origin xyz="0.0 -0.02 0.035" rpy="0 0 0"/>
  <parent link="arm_link1_v1_1"/>
  <child link="arm_axle1_v2_1"/>
</joint>

<joint name="rigid_set1" type="fixed">
  <origin xyz="0.0 0.01 0.135" rpy="0 0 0"/>
  <parent link="arm_set_v1_1"/>
  <child link="arm_link2_v2_1"/>
</joint>

<joint name="joint_05" type="continuous">
  <origin xyz="0.0 -0.01 0.035" rpy="0 0 0"/>
  <parent link="arm_link2_v2_1"/>
  <child link="arm_set2_v1_1"/>
  <axis xyz="0.0 1.0 0.0"/>
</joint>

<joint name="rigid_axle2" type="fixed">
  <origin xyz="0.0 -0.02 0.035" rpy="0 0 0"/>
  <parent link="arm_link2_v2_1"/>
  <child link="arm_axle2_v1_1"/>
</joint>

<joint name="rigid_set2" type="fixed">
  <origin xyz="0.135 0.01 0.0" rpy="0 0 0"/>
  <parent link="arm_set2_v1_1"/>
  <child link="gripper_set_v2_1"/>
</joint>

<joint name="left_slider" type="prismatic">
  <origin xyz="0.015 0.04 0.0" rpy="0 0 0"/>
  <parent link="gripper_set_v2_1"/>
  <child link="gripper_llink_v3_1"/>
  <axis xyz="0.0 1.0 -0.0"/>
  <limit upper="0.0" lower="0.0" effort="100" velocity="100"/>
</joint>

<joint name="rgid_left" type="fixed">
  <origin xyz="0.027 0.0 0.0" rpy="0 0 0"/>
  <parent link="gripper_llink_v3_1"/>
  <child link="gripper_left_v3_1"/>
</joint>

<joint name="right_slider" type="prismatic">
  <origin xyz="0.015 -0.04 0.0" rpy="0 0 0"/>
  <parent link="gripper_set_v2_1"/>
  <child link="gripper_rlink_v3_1"/>
  <axis xyz="0.0 1.0 -0.0"/>
  <limit upper="0.0" lower="0.0" effort="100" velocity="100"/>
</joint>

<joint name="rigid_right" type="fixed">
  <origin xyz="0.027 0.0 0.0" rpy="0 0 0"/>
  <parent link="gripper_rlink_v3_1"/>
  <child link="gripper_right_v2_1"/>
</joint>

</robot>
